<?xml version="1.0"?>
<robot xmlns:xacro="http://www.ros.org/wiki/xacro">

    <xacro:include filename="macros.xacro"/>

    <material name="white">
        <color rgba="1 1 1 1"/>
    </material>

    <material name="orange">
        <color rgba="1 0.3 0.1 1"/>
    </material>
    
    <material name="blue">
        <color rgba="0.2 0.2 1 1"/>
    </material>
    
    <material name="black">
        <color rgba="0 0 0 1"/>
    </material>

    <material name="red">
        <color rgba="1 0 0 1"/>
    </material>

    <link name="base_link">
    </link>

    <joint name="chassis_link" type="fixed">
        <parent link="base_link"/>
        <child link="chassis"/>
    </joint>
    
    <link name="chassis">
        <visual>
            <origin xyz="0 0 0.15" />
            <geometry>
            <box size="0.8 0.8 0.3"/>
            </geometry>
            <material name="orange"/>
        </visual>
        <collision>
            <origin xyz="0 0 0.15" />
            <geometry>
            <box size="0.8 0.8 0.3"/>
            </geometry>
            <material name="orange"/>
        </collision>
        <xacro:inertial_box mass="20.5" x="0.8" y="0.8" z="0.3"> 
            <origin xyz="0 0 0.15" rpy="0 0 0"/>
        </xacro:inertial_box>
    </link>

    <gazebo reference="chassis">
        <material>Gazebo/Red</material>
    </gazebo>

    <joint name="FL_wheel_link" type="continuous">
       <parent link="chassis"/>
       <child link="FL_wheel"/>
       <origin xyz="0.2 0.45 0" rpy="-${pi/2} 0 0"/>
       <axis xyz="0 0 1"/>
    </joint>

    <link name="FL_wheel">
        <visual>
            <origin xyz="0 0 0" />
            <geometry>
                <cylinder length="0.1" radius="0.1"/>
            </geometry>
            <material name="white"/>
        </visual>
        <collision>
            <origin xyz="0 0 0" />
            <geometry>
                <cylinder length="0.1" radius="0.1"/>
            </geometry>
        </collision>
        <xacro:inertial_cylinder mass="0.5" length="0.1" radius="0.1"> 
            <origin xyz="0 0 0" rpy="0 0 0"/>
        </xacro:inertial_cylinder>
    </link>

    <gazebo reference="FL_wheel">
        <material>Gazebo/White</material>
        <mu1 value="0.8"/>
        <mu2 value="0.8"/>
    </gazebo>

    <joint name="FR_wheel_link" type="continuous">
        <parent link="chassis"/>
        <child link="FR_wheel"/>
        <origin xyz="0.2 -0.45 0" rpy="${pi/2} 0 0"/>
        <axis xyz="0 0 -1"/>
    </joint>

    <link name="FR_wheel">
        <visual>
            <origin xyz="0 0 0"  />
            <geometry>
                <cylinder length="0.1" radius="0.1"/>
            </geometry>
            <material name="white"/>
        </visual>
        <collision>
            <origin xyz="0 0 0" />
            <geometry>
                <cylinder length="0.1" radius="0.1"/>
            </geometry>
        </collision>
        <xacro:inertial_cylinder mass="0.5" length="0.1" radius="0.1"> 
            <origin xyz="0 0 0" rpy="0 0 0"/>
        </xacro:inertial_cylinder>
    </link>

    <gazebo reference="FR_wheel">
        <material>Gazebo/White</material>
        <mu1 value="0.8"/>
        <mu2 value="0.8"/>
    </gazebo>

    <joint name="BL_wheel_link" type="continuous">
        <parent link="chassis"/>
        <child link="BL_wheel"/>
        <origin xyz="-0.2 0.45 0" rpy="-${pi/2} 0 0"/>
        <axis xyz="0 0 1"/>
    </joint>

    <link name="BL_wheel">
        <visual>
            <origin xyz="0 0 0" />
            <geometry>
                <cylinder length="0.1" radius="0.1"/>
            </geometry>
            <material name="white"/>
        </visual>
        <collision>
            <origin xyz="0 0 0" />
            <geometry>
                <cylinder length="0.1" radius="0.1"/>
            </geometry>
        </collision>
        <xacro:inertial_cylinder mass="0.5" length="0.1" radius="0.1"> 
            <origin xyz="0 0 0" rpy="0 0 0"/>
        </xacro:inertial_cylinder>
    </link>

    <gazebo reference="BL_wheel">
        <material>Gazebo/White</material>
        <mu1 value="0.8"/>
        <mu2 value="0.8"/>
    </gazebo>

    <joint name="BR_wheel_link" type="continuous">
        <parent link="chassis"/>
        <child link="BR_wheel"/>
        <origin xyz="-0.2 -0.45 0" rpy="${pi/2} 0 0"/>
        <axis xyz="0 0 -1"/>
    </joint>

    <link name="BR_wheel">
        <visual>
            <origin xyz="0 0 0" />
            <geometry>
                <cylinder length="0.1" radius="0.1"/>
            </geometry>
            <material name="white"/>
        </visual>
        <collision>
            <origin xyz="0 0 0" />
            <geometry>
                <cylinder length="0.1" radius="0.1"/>
            </geometry>
        </collision>
        <xacro:inertial_cylinder mass="0.5" length="0.1" radius="0.1"> 
            <origin xyz="0 0 0" rpy="0 0 0"/>
        </xacro:inertial_cylinder>
    </link>

    <gazebo reference="BR_wheel">
        <material>Gazebo/White</material>
        <mu1 value="0.8"/>
        <mu2 value="0.8"/>
    </gazebo>

</robot>